python -u "c:\Users\kulka\Downloads\PersonalBudgetTracker\main.py"
Traceback (most recent call last):
  File "C:\Users\kulka\AppData\Local\Programs\Python\Python312\Lib\site-packages\sqlalchemy\engine\base.py", line 146, in __init__
    self._dbapi_connection = engine.raw_connection()
                             ^^^^^^^^^^^^^^^^^^^^^^^
  File "C:\Users\kulka\AppData\Local\Programs\Python\Python312\Lib\site-packages\sqlalchemy\engine\base.py", line 3298, in raw_connection
    return self.pool.connect()
           ^^^^^^^^^^^^^^^^^^^
  File "C:\Users\kulka\AppData\Local\Programs\Python\Python312\Lib\site-packages\sqlalchemy\pool\base.py", line 449, in connect
    return _ConnectionFairy._checkout(self)
           ^^^^^^^^^^^^^^^^^^^^^^^^^^^^^^^^
  File "C:\Users\kulka\AppData\Local\Programs\Python\Python312\Lib\site-packages\sqlalchemy\pool\base.py", line 1264, in _checkout
    fairy = _ConnectionRecord.checkout(pool)
            ^^^^^^^^^^^^^^^^^^^^^^^^^^^^^^^^
  File "C:\Users\kulka\AppData\Local\Programs\Python\Python312\Lib\site-packages\sqlalchemy\pool\base.py", line 713, in checkout
    rec = pool._do_get()
          ^^^^^^^^^^^^^^
  File "C:\Users\kulka\AppData\Local\Programs\Python\Python312\Lib\site-packages\sqlalchemy\pool\impl.py", line 179, in _do_get
    with util.safe_reraise():
  File "C:\Users\kulka\AppData\Local\Programs\Python\Python312\Lib\site-packages\sqlalchemy\util\langhelpers.py", line 146, in __exit__
    raise exc_value.with_traceback(exc_tb)
  File "C:\Users\kulka\AppData\Local\Programs\Python\Python312\Lib\site-packages\sqlalchemy\pool\impl.py", line 177, in _do_get
    return self._create_connection()
           ^^^^^^^^^^^^^^^^^^^^^^^^^
  File "C:\Users\kulka\AppData\Local\Programs\Python\Python312\Lib\site-packages\sqlalchemy\pool\base.py", line 390, in _create_connection
    return _ConnectionRecord(self)
           ^^^^^^^^^^^^^^^^^^^^^^^
  File "C:\Users\kulka\AppData\Local\Programs\Python\Python312\Lib\site-packages\sqlalchemy\pool\base.py", line 675, in __init__
    self.__connect()
  File "C:\Users\kulka\AppData\Local\Programs\Python\Python312\Lib\site-packages\sqlalchemy\pool\base.py", line 901, in __connect
    with util.safe_reraise():
  File "C:\Users\kulka\AppData\Local\Programs\Python\Python312\Lib\site-packages\sqlalchemy\util\langhelpers.py", line 146, in __exit__
    raise exc_value.with_traceback(exc_tb)
  File "C:\Users\kulka\AppData\Local\Programs\Python\Python312\Lib\site-packages\sqlalchemy\pool\base.py", line 897, in __connect
    self.dbapi_connection = connection = pool._invoke_creator(self)
                                         ^^^^^^^^^^^^^^^^^^^^^^^^^^
  File "C:\Users\kulka\AppData\Local\Programs\Python\Python312\Lib\site-packages\sqlalchemy\engine\create.py", line 646, in connect
    return dialect.connect(*cargs, **cparams)
           ^^^^^^^^^^^^^^^^^^^^^^^^^^^^^^^^^^
  File "C:\Users\kulka\AppData\Local\Programs\Python\Python312\Lib\site-packages\sqlalchemy\engine\default.py", line 625, in connect
    return self.loaded_dbapi.connect(*cargs, **cparams)  # type: ignore[no-any-return]  # NOQA: E501
           ^^^^^^^^^^^^^^^^^^^^^^^^^^^^^^^^^^^^^^^^^^^^
pyodbc.InterfaceError: ('28000', "[28000] [Microsoft][ODBC Driver 17 for SQL Server][SQL Server]Login failed for user 'NAME\\kulka'. (18456) (SQLDriverConnect); [28000] [Microsoft][ODBC Driver 17 for SQL Server][SQL Server]Login failed for user 'NAME\\kulka'. (18456)")

The above exception was the direct cause of the following exception:

Traceback (most recent call last):
  File "c:\Users\kulka\Downloads\PersonalBudgetTracker\main.py", line 12, in <module>
    from app import app, db
  File "c:\Users\kulka\Downloads\PersonalBudgetTracker\app.py", line 39, in <module>
    db.create_all()
  File "C:\Users\kulka\AppData\Local\Programs\Python\Python312\Lib\site-packages\flask_sqlalchemy\extension.py", line 900, in create_all
    self._call_for_binds(bind_key, "create_all")
  File "C:\Users\kulka\AppData\Local\Programs\Python\Python312\Lib\site-packages\flask_sqlalchemy\extension.py", line 881, in _call_for_binds
    getattr(metadata, op_name)(bind=engine)
  File "C:\Users\kulka\AppData\Local\Programs\Python\Python312\Lib\site-packages\sqlalchemy\sql\schema.py", line 5925, in create_all
    bind._run_ddl_visitor(
  File "C:\Users\kulka\AppData\Local\Programs\Python\Python312\Lib\site-packages\sqlalchemy\engine\base.py", line 3248, in _run_ddl_visitor
    with self.begin() as conn:
  File "C:\Users\kulka\AppData\Local\Programs\Python\Python312\Lib\contextlib.py", line 137, in __enter__
    return next(self.gen)
           ^^^^^^^^^^^^^^
  File "C:\Users\kulka\AppData\Local\Programs\Python\Python312\Lib\site-packages\sqlalchemy\engine\base.py", line 3238, in begin
    with self.connect() as conn:
         ^^^^^^^^^^^^^^
  File "C:\Users\kulka\AppData\Local\Programs\Python\Python312\Lib\site-packages\sqlalchemy\engine\base.py", line 3274, in connect
    return self._connection_cls(self)
           ^^^^^^^^^^^^^^^^^^^^^^^^^^
  File "C:\Users\kulka\AppData\Local\Programs\Python\Python312\Lib\site-packages\sqlalchemy\engine\base.py", line 148, in __init__
    Connection._handle_dbapi_exception_noconnection(
  File "C:\Users\kulka\AppData\Local\Programs\Python\Python312\Lib\site-packages\sqlalchemy\engine\base.py", line 2439, in _handle_dbapi_exception_noconnection
    raise sqlalchemy_exception.with_traceback(exc_info[2]) from e
  File "C:\Users\kulka\AppData\Local\Programs\Python\Python312\Lib\site-packages\sqlalchemy\engine\base.py", line 146, in __init__
    self._dbapi_connection = engine.raw_connection()
                             ^^^^^^^^^^^^^^^^^^^^^^^
  File "C:\Users\kulka\AppData\Local\Programs\Python\Python312\Lib\site-packages\sqlalchemy\engine\base.py", line 3298, in raw_connection
    return self.pool.connect()
           ^^^^^^^^^^^^^^^^^^^
  File "C:\Users\kulka\AppData\Local\Programs\Python\Python312\Lib\site-packages\sqlalchemy\pool\base.py", line 449, in connect
    return _ConnectionFairy._checkout(self)
           ^^^^^^^^^^^^^^^^^^^^^^^^^^^^^^^^
  File "C:\Users\kulka\AppData\Local\Programs\Python\Python312\Lib\site-packages\sqlalchemy\pool\base.py", line 1264, in _checkout
    fairy = _ConnectionRecord.checkout(pool)
            ^^^^^^^^^^^^^^^^^^^^^^^^^^^^^^^^
  File "C:\Users\kulka\AppData\Local\Programs\Python\Python312\Lib\site-packages\sqlalchemy\pool\base.py", line 713, in checkout
    rec = pool._do_get()
          ^^^^^^^^^^^^^^
  File "C:\Users\kulka\AppData\Local\Programs\Python\Python312\Lib\site-packages\sqlalchemy\pool\impl.py", line 179, in _do_get
    with util.safe_reraise():
  File "C:\Users\kulka\AppData\Local\Programs\Python\Python312\Lib\site-packages\sqlalchemy\util\langhelpers.py", line 146, in __exit__
    raise exc_value.with_traceback(exc_tb)
  File "C:\Users\kulka\AppData\Local\Programs\Python\Python312\Lib\site-packages\sqlalchemy\pool\impl.py", line 177, in _do_get
    return self._create_connection()
           ^^^^^^^^^^^^^^^^^^^^^^^^^
  File "C:\Users\kulka\AppData\Local\Programs\Python\Python312\Lib\site-packages\sqlalchemy\pool\base.py", line 390, in _create_connection
    return _ConnectionRecord(self)
           ^^^^^^^^^^^^^^^^^^^^^^^
  File "C:\Users\kulka\AppData\Local\Programs\Python\Python312\Lib\site-packages\sqlalchemy\pool\base.py", line 675, in __init__
    self.__connect()
  File "C:\Users\kulka\AppData\Local\Programs\Python\Python312\Lib\site-packages\sqlalchemy\pool\base.py", line 901, in __connect
    with util.safe_reraise():
  File "C:\Users\kulka\AppData\Local\Programs\Python\Python312\Lib\site-packages\sqlalchemy\util\langhelpers.py", line 146, in __exit__
    raise exc_value.with_traceback(exc_tb)
  File "C:\Users\kulka\AppData\Local\Programs\Python\Python312\Lib\site-packages\sqlalchemy\pool\base.py", line 897, in __connect
    self.dbapi_connection = connection = pool._invoke_creator(self)
                                         ^^^^^^^^^^^^^^^^^^^^^^^^^^
  File "C:\Users\kulka\AppData\Local\Programs\Python\Python312\Lib\site-packages\sqlalchemy\engine\create.py", line 646, in connect
    return dialect.connect(*cargs, **cparams)
           ^^^^^^^^^^^^^^^^^^^^^^^^^^^^^^^^^^
  File "C:\Users\kulka\AppData\Local\Programs\Python\Python312\Lib\site-packages\sqlalchemy\engine\default.py", line 625, in connect
    return self.loaded_dbapi.connect(*cargs, **cparams)  # type: ignore[no-any-return]  # NOQA: E501
           ^^^^^^^^^^^^^^^^^^^^^^^^^^^^^^^^^^^^^^^^^^^^
sqlalchemy.exc.InterfaceError: (pyodbc.InterfaceError) ('28000', "[28000] [Microsoft][ODBC Driver 17 for SQL Server][SQL Server]Login failed for user 'NAME\\kulka'. (18456) (SQLDriverConnect); [28000] [Microsoft][ODBC Driver 17 for SQL Server][SQL Server]Login failed for user 'NAME\\kulka'. (18456)")
(Background on this error at: https://sqlalche.me/e/20/rvf5)

[Done] exited with code=1 in 0.735 seconds

